console.log(a + b);
console.log("This line is never reached");

// throw new ReferenceError();


try{
    console.log(a + b);
}
catch(err){
    console.log(err)
    console.log('There was an error');
    console.log('The error was saved in the error log');
}
console.log('My program does not stop');



try{
    throw new ReferenceError();
}
catch(err){
    console.log(err);
    console.log('There was a Reference Error');
}
console.log('My Program does not stop');

